Failure # 1 (occurred at 2021-10-31_12-51-44)
Traceback (most recent call last):
  File "/home/setsumi/miniconda3/envs/pytorch_env/lib/python3.7/site-packages/ray/tune/trial_runner.py", line 812, in _process_trial
    results = self.trial_executor.fetch_result(trial)
  File "/home/setsumi/miniconda3/envs/pytorch_env/lib/python3.7/site-packages/ray/tune/ray_trial_executor.py", line 767, in fetch_result
    result = ray.get(trial_future[0], timeout=DEFAULT_GET_TIMEOUT)
  File "/home/setsumi/miniconda3/envs/pytorch_env/lib/python3.7/site-packages/ray/_private/client_mode_hook.py", line 89, in wrapper
    return func(*args, **kwargs)
  File "/home/setsumi/miniconda3/envs/pytorch_env/lib/python3.7/site-packages/ray/worker.py", line 1621, in get
    raise value.as_instanceof_cause()
ray.exceptions.RayTaskError(TuneError): [36mray::ImplicitFunc.train_buffered()[39m (pid=5671, ip=192.168.0.11, repr=<types.ImplicitFunc object at 0x7f81917ffd50>)
  File "/home/setsumi/miniconda3/envs/pytorch_env/lib/python3.7/site-packages/ray/tune/trainable.py", line 189, in train_buffered
    result = self.train()
  File "/home/setsumi/miniconda3/envs/pytorch_env/lib/python3.7/site-packages/ray/tune/trainable.py", line 248, in train
    result = self.step()
  File "/home/setsumi/miniconda3/envs/pytorch_env/lib/python3.7/site-packages/ray/tune/function_runner.py", line 379, in step
    self._report_thread_runner_error(block=True)
  File "/home/setsumi/miniconda3/envs/pytorch_env/lib/python3.7/site-packages/ray/tune/function_runner.py", line 527, in _report_thread_runner_error
    ("Trial raised an exception. Traceback:\n{}".format(err_tb_str)
ray.tune.error.TuneError: Trial raised an exception. Traceback:
[36mray::ImplicitFunc.train_buffered()[39m (pid=5671, ip=192.168.0.11, repr=<types.ImplicitFunc object at 0x7f81917ffd50>)
  File "/home/setsumi/miniconda3/envs/pytorch_env/lib/python3.7/site-packages/ray/tune/function_runner.py", line 260, in run
    self._entrypoint()
  File "/home/setsumi/miniconda3/envs/pytorch_env/lib/python3.7/site-packages/ray/tune/function_runner.py", line 329, in entrypoint
    self._status_reporter.get_checkpoint())
  File "/home/setsumi/miniconda3/envs/pytorch_env/lib/python3.7/site-packages/ray/tune/function_runner.py", line 594, in _trainable_func
    output = fn()
  File "train.py", line 169, in training_f
    plt.savefig(f"lr:{config['lr']}_epochs:{config['epochs']}_sche_id:{config['sche_id']}_optim_id:{config['optim_id']}")
  File "/home/setsumi/miniconda3/envs/pytorch_env/lib/python3.7/site-packages/matplotlib/pyplot.py", line 966, in savefig
    res = fig.savefig(*args, **kwargs)
  File "/home/setsumi/miniconda3/envs/pytorch_env/lib/python3.7/site-packages/matplotlib/figure.py", line 3015, in savefig
    self.canvas.print_figure(fname, **kwargs)
  File "/home/setsumi/miniconda3/envs/pytorch_env/lib/python3.7/site-packages/matplotlib/backend_bases.py", line 2186, in print_figure
    canvas = self._get_output_canvas(backend, format)
  File "/home/setsumi/miniconda3/envs/pytorch_env/lib/python3.7/site-packages/matplotlib/backend_bases.py", line 2117, in _get_output_canvas
    .format(fmt, ", ".join(sorted(self.get_supported_filetypes()))))
ValueError: Format '1_epochs:50_sche_id:4_optim_id:1' is not supported (supported formats: eps, jpeg, jpg, pdf, pgf, png, ps, raw, rgba, svg, svgz, tif, tiff)

